{
  "nbformat": 4,
  "nbformat_minor": 0,
  "metadata": {
    "colab": {
      "provenance": [],
      "authorship_tag": "ABX9TyM/Bd2g0i6fk4eg/25JjEfF"
    },
    "kernelspec": {
      "name": "python3",
      "display_name": "Python 3"
    },
    "language_info": {
      "name": "python"
    }
  },
  "cells": [
    {
      "cell_type": "code",
      "execution_count": null,
      "metadata": {
        "colab": {
          "base_uri": "https://localhost:8080/",
          "height": 1000
        },
        "id": "yOcsbQ-FgMks",
        "outputId": "a3ef37ce-5d87-43fa-a4e7-b2e73d09769c"
      },
      "outputs": [
        {
          "output_type": "stream",
          "name": "stderr",
          "text": [
            "/usr/local/lib/python3.10/dist-packages/sklearn/preprocessing/_label.py:116: DataConversionWarning: A column-vector y was passed when a 1d array was expected. Please change the shape of y to (n_samples, ), for example using ravel().\n",
            "  y = column_or_1d(y, warn=True)\n"
          ]
        },
        {
          "output_type": "stream",
          "name": "stdout",
          "text": [
            "Epoch 1/10\n"
          ]
        },
        {
          "output_type": "error",
          "ename": "InvalidArgumentError",
          "evalue": "Graph execution error:\n\nDetected at node sparse_categorical_crossentropy/SparseSoftmaxCrossEntropyWithLogits/SparseSoftmaxCrossEntropyWithLogits defined at (most recent call last):\n  File \"/usr/lib/python3.10/runpy.py\", line 196, in _run_module_as_main\n\n  File \"/usr/lib/python3.10/runpy.py\", line 86, in _run_code\n\n  File \"/usr/local/lib/python3.10/dist-packages/colab_kernel_launcher.py\", line 37, in <module>\n\n  File \"/usr/local/lib/python3.10/dist-packages/traitlets/config/application.py\", line 992, in launch_instance\n\n  File \"/usr/local/lib/python3.10/dist-packages/ipykernel/kernelapp.py\", line 619, in start\n\n  File \"/usr/local/lib/python3.10/dist-packages/tornado/platform/asyncio.py\", line 195, in start\n\n  File \"/usr/lib/python3.10/asyncio/base_events.py\", line 603, in run_forever\n\n  File \"/usr/lib/python3.10/asyncio/base_events.py\", line 1909, in _run_once\n\n  File \"/usr/lib/python3.10/asyncio/events.py\", line 80, in _run\n\n  File \"/usr/local/lib/python3.10/dist-packages/tornado/ioloop.py\", line 685, in <lambda>\n\n  File \"/usr/local/lib/python3.10/dist-packages/tornado/ioloop.py\", line 738, in _run_callback\n\n  File \"/usr/local/lib/python3.10/dist-packages/tornado/gen.py\", line 825, in inner\n\n  File \"/usr/local/lib/python3.10/dist-packages/tornado/gen.py\", line 786, in run\n\n  File \"/usr/local/lib/python3.10/dist-packages/ipykernel/kernelbase.py\", line 361, in process_one\n\n  File \"/usr/local/lib/python3.10/dist-packages/tornado/gen.py\", line 234, in wrapper\n\n  File \"/usr/local/lib/python3.10/dist-packages/ipykernel/kernelbase.py\", line 261, in dispatch_shell\n\n  File \"/usr/local/lib/python3.10/dist-packages/tornado/gen.py\", line 234, in wrapper\n\n  File \"/usr/local/lib/python3.10/dist-packages/ipykernel/kernelbase.py\", line 539, in execute_request\n\n  File \"/usr/local/lib/python3.10/dist-packages/tornado/gen.py\", line 234, in wrapper\n\n  File \"/usr/local/lib/python3.10/dist-packages/ipykernel/ipkernel.py\", line 302, in do_execute\n\n  File \"/usr/local/lib/python3.10/dist-packages/ipykernel/zmqshell.py\", line 539, in run_cell\n\n  File \"/usr/local/lib/python3.10/dist-packages/IPython/core/interactiveshell.py\", line 2975, in run_cell\n\n  File \"/usr/local/lib/python3.10/dist-packages/IPython/core/interactiveshell.py\", line 3030, in _run_cell\n\n  File \"/usr/local/lib/python3.10/dist-packages/IPython/core/async_helpers.py\", line 78, in _pseudo_sync_runner\n\n  File \"/usr/local/lib/python3.10/dist-packages/IPython/core/interactiveshell.py\", line 3257, in run_cell_async\n\n  File \"/usr/local/lib/python3.10/dist-packages/IPython/core/interactiveshell.py\", line 3473, in run_ast_nodes\n\n  File \"/usr/local/lib/python3.10/dist-packages/IPython/core/interactiveshell.py\", line 3553, in run_code\n\n  File \"<ipython-input-9-ca4c80e384f0>\", line 59, in <cell line: 59>\n\n  File \"/usr/local/lib/python3.10/dist-packages/keras/src/utils/traceback_utils.py\", line 65, in error_handler\n\n  File \"/usr/local/lib/python3.10/dist-packages/keras/src/engine/training.py\", line 1807, in fit\n\n  File \"/usr/local/lib/python3.10/dist-packages/keras/src/engine/training.py\", line 1401, in train_function\n\n  File \"/usr/local/lib/python3.10/dist-packages/keras/src/engine/training.py\", line 1384, in step_function\n\n  File \"/usr/local/lib/python3.10/dist-packages/keras/src/engine/training.py\", line 1373, in run_step\n\n  File \"/usr/local/lib/python3.10/dist-packages/keras/src/engine/training.py\", line 1151, in train_step\n\n  File \"/usr/local/lib/python3.10/dist-packages/keras/src/engine/training.py\", line 1209, in compute_loss\n\n  File \"/usr/local/lib/python3.10/dist-packages/keras/src/engine/compile_utils.py\", line 277, in __call__\n\n  File \"/usr/local/lib/python3.10/dist-packages/keras/src/losses.py\", line 143, in __call__\n\n  File \"/usr/local/lib/python3.10/dist-packages/keras/src/losses.py\", line 270, in call\n\n  File \"/usr/local/lib/python3.10/dist-packages/keras/src/losses.py\", line 2454, in sparse_categorical_crossentropy\n\n  File \"/usr/local/lib/python3.10/dist-packages/keras/src/backend.py\", line 5775, in sparse_categorical_crossentropy\n\nReceived a label value of 1380 which is outside the valid range of [0, 1147).  Label values: 176 1061 1022 514 14 588 78 598 1076 522 208 231 815 840 882 361 641 364 361 602 361 1219 812 1380 990 842 1363 598 1005 703 273 73 572 885 361 387 151 74 281 11 385 545 47 713 310 1202 106 1258 60 703 499 737 364 585 593 141 246 935 930 1222 43 61 151 109\n\t [[{{node sparse_categorical_crossentropy/SparseSoftmaxCrossEntropyWithLogits/SparseSoftmaxCrossEntropyWithLogits}}]] [Op:__inference_train_function_4543]",
          "traceback": [
            "\u001b[0;31m---------------------------------------------------------------------------\u001b[0m",
            "\u001b[0;31mInvalidArgumentError\u001b[0m                      Traceback (most recent call last)",
            "\u001b[0;32m<ipython-input-9-ca4c80e384f0>\u001b[0m in \u001b[0;36m<cell line: 59>\u001b[0;34m()\u001b[0m\n\u001b[1;32m     57\u001b[0m \u001b[0;34m\u001b[0m\u001b[0m\n\u001b[1;32m     58\u001b[0m \u001b[0;31m# 모델 훈련\u001b[0m\u001b[0;34m\u001b[0m\u001b[0;34m\u001b[0m\u001b[0m\n\u001b[0;32m---> 59\u001b[0;31m \u001b[0mmodel\u001b[0m\u001b[0;34m.\u001b[0m\u001b[0mfit\u001b[0m\u001b[0;34m(\u001b[0m\u001b[0mX_train\u001b[0m\u001b[0;34m,\u001b[0m \u001b[0my_train\u001b[0m\u001b[0;34m,\u001b[0m \u001b[0mepochs\u001b[0m\u001b[0;34m=\u001b[0m\u001b[0;36m10\u001b[0m\u001b[0;34m,\u001b[0m \u001b[0mbatch_size\u001b[0m\u001b[0;34m=\u001b[0m\u001b[0;36m64\u001b[0m\u001b[0;34m,\u001b[0m \u001b[0mvalidation_split\u001b[0m\u001b[0;34m=\u001b[0m\u001b[0;36m0.2\u001b[0m\u001b[0;34m)\u001b[0m\u001b[0;34m\u001b[0m\u001b[0;34m\u001b[0m\u001b[0m\n\u001b[0m",
            "\u001b[0;32m/usr/local/lib/python3.10/dist-packages/keras/src/utils/traceback_utils.py\u001b[0m in \u001b[0;36merror_handler\u001b[0;34m(*args, **kwargs)\u001b[0m\n\u001b[1;32m     68\u001b[0m             \u001b[0;31m# To get the full stack trace, call:\u001b[0m\u001b[0;34m\u001b[0m\u001b[0;34m\u001b[0m\u001b[0m\n\u001b[1;32m     69\u001b[0m             \u001b[0;31m# `tf.debugging.disable_traceback_filtering()`\u001b[0m\u001b[0;34m\u001b[0m\u001b[0;34m\u001b[0m\u001b[0m\n\u001b[0;32m---> 70\u001b[0;31m             \u001b[0;32mraise\u001b[0m \u001b[0me\u001b[0m\u001b[0;34m.\u001b[0m\u001b[0mwith_traceback\u001b[0m\u001b[0;34m(\u001b[0m\u001b[0mfiltered_tb\u001b[0m\u001b[0;34m)\u001b[0m \u001b[0;32mfrom\u001b[0m \u001b[0;32mNone\u001b[0m\u001b[0;34m\u001b[0m\u001b[0;34m\u001b[0m\u001b[0m\n\u001b[0m\u001b[1;32m     71\u001b[0m         \u001b[0;32mfinally\u001b[0m\u001b[0;34m:\u001b[0m\u001b[0;34m\u001b[0m\u001b[0;34m\u001b[0m\u001b[0m\n\u001b[1;32m     72\u001b[0m             \u001b[0;32mdel\u001b[0m \u001b[0mfiltered_tb\u001b[0m\u001b[0;34m\u001b[0m\u001b[0;34m\u001b[0m\u001b[0m\n",
            "\u001b[0;32m/usr/local/lib/python3.10/dist-packages/tensorflow/python/eager/execute.py\u001b[0m in \u001b[0;36mquick_execute\u001b[0;34m(op_name, num_outputs, inputs, attrs, ctx, name)\u001b[0m\n\u001b[1;32m     51\u001b[0m   \u001b[0;32mtry\u001b[0m\u001b[0;34m:\u001b[0m\u001b[0;34m\u001b[0m\u001b[0;34m\u001b[0m\u001b[0m\n\u001b[1;32m     52\u001b[0m     \u001b[0mctx\u001b[0m\u001b[0;34m.\u001b[0m\u001b[0mensure_initialized\u001b[0m\u001b[0;34m(\u001b[0m\u001b[0;34m)\u001b[0m\u001b[0;34m\u001b[0m\u001b[0;34m\u001b[0m\u001b[0m\n\u001b[0;32m---> 53\u001b[0;31m     tensors = pywrap_tfe.TFE_Py_Execute(ctx._handle, device_name, op_name,\n\u001b[0m\u001b[1;32m     54\u001b[0m                                         inputs, attrs, num_outputs)\n\u001b[1;32m     55\u001b[0m   \u001b[0;32mexcept\u001b[0m \u001b[0mcore\u001b[0m\u001b[0;34m.\u001b[0m\u001b[0m_NotOkStatusException\u001b[0m \u001b[0;32mas\u001b[0m \u001b[0me\u001b[0m\u001b[0;34m:\u001b[0m\u001b[0;34m\u001b[0m\u001b[0;34m\u001b[0m\u001b[0m\n",
            "\u001b[0;31mInvalidArgumentError\u001b[0m: Graph execution error:\n\nDetected at node sparse_categorical_crossentropy/SparseSoftmaxCrossEntropyWithLogits/SparseSoftmaxCrossEntropyWithLogits defined at (most recent call last):\n  File \"/usr/lib/python3.10/runpy.py\", line 196, in _run_module_as_main\n\n  File \"/usr/lib/python3.10/runpy.py\", line 86, in _run_code\n\n  File \"/usr/local/lib/python3.10/dist-packages/colab_kernel_launcher.py\", line 37, in <module>\n\n  File \"/usr/local/lib/python3.10/dist-packages/traitlets/config/application.py\", line 992, in launch_instance\n\n  File \"/usr/local/lib/python3.10/dist-packages/ipykernel/kernelapp.py\", line 619, in start\n\n  File \"/usr/local/lib/python3.10/dist-packages/tornado/platform/asyncio.py\", line 195, in start\n\n  File \"/usr/lib/python3.10/asyncio/base_events.py\", line 603, in run_forever\n\n  File \"/usr/lib/python3.10/asyncio/base_events.py\", line 1909, in _run_once\n\n  File \"/usr/lib/python3.10/asyncio/events.py\", line 80, in _run\n\n  File \"/usr/local/lib/python3.10/dist-packages/tornado/ioloop.py\", line 685, in <lambda>\n\n  File \"/usr/local/lib/python3.10/dist-packages/tornado/ioloop.py\", line 738, in _run_callback\n\n  File \"/usr/local/lib/python3.10/dist-packages/tornado/gen.py\", line 825, in inner\n\n  File \"/usr/local/lib/python3.10/dist-packages/tornado/gen.py\", line 786, in run\n\n  File \"/usr/local/lib/python3.10/dist-packages/ipykernel/kernelbase.py\", line 361, in process_one\n\n  File \"/usr/local/lib/python3.10/dist-packages/tornado/gen.py\", line 234, in wrapper\n\n  File \"/usr/local/lib/python3.10/dist-packages/ipykernel/kernelbase.py\", line 261, in dispatch_shell\n\n  File \"/usr/local/lib/python3.10/dist-packages/tornado/gen.py\", line 234, in wrapper\n\n  File \"/usr/local/lib/python3.10/dist-packages/ipykernel/kernelbase.py\", line 539, in execute_request\n\n  File \"/usr/local/lib/python3.10/dist-packages/tornado/gen.py\", line 234, in wrapper\n\n  File \"/usr/local/lib/python3.10/dist-packages/ipykernel/ipkernel.py\", line 302, in do_execute\n\n  File \"/usr/local/lib/python3.10/dist-packages/ipykernel/zmqshell.py\", line 539, in run_cell\n\n  File \"/usr/local/lib/python3.10/dist-packages/IPython/core/interactiveshell.py\", line 2975, in run_cell\n\n  File \"/usr/local/lib/python3.10/dist-packages/IPython/core/interactiveshell.py\", line 3030, in _run_cell\n\n  File \"/usr/local/lib/python3.10/dist-packages/IPython/core/async_helpers.py\", line 78, in _pseudo_sync_runner\n\n  File \"/usr/local/lib/python3.10/dist-packages/IPython/core/interactiveshell.py\", line 3257, in run_cell_async\n\n  File \"/usr/local/lib/python3.10/dist-packages/IPython/core/interactiveshell.py\", line 3473, in run_ast_nodes\n\n  File \"/usr/local/lib/python3.10/dist-packages/IPython/core/interactiveshell.py\", line 3553, in run_code\n\n  File \"<ipython-input-9-ca4c80e384f0>\", line 59, in <cell line: 59>\n\n  File \"/usr/local/lib/python3.10/dist-packages/keras/src/utils/traceback_utils.py\", line 65, in error_handler\n\n  File \"/usr/local/lib/python3.10/dist-packages/keras/src/engine/training.py\", line 1807, in fit\n\n  File \"/usr/local/lib/python3.10/dist-packages/keras/src/engine/training.py\", line 1401, in train_function\n\n  File \"/usr/local/lib/python3.10/dist-packages/keras/src/engine/training.py\", line 1384, in step_function\n\n  File \"/usr/local/lib/python3.10/dist-packages/keras/src/engine/training.py\", line 1373, in run_step\n\n  File \"/usr/local/lib/python3.10/dist-packages/keras/src/engine/training.py\", line 1151, in train_step\n\n  File \"/usr/local/lib/python3.10/dist-packages/keras/src/engine/training.py\", line 1209, in compute_loss\n\n  File \"/usr/local/lib/python3.10/dist-packages/keras/src/engine/compile_utils.py\", line 277, in __call__\n\n  File \"/usr/local/lib/python3.10/dist-packages/keras/src/losses.py\", line 143, in __call__\n\n  File \"/usr/local/lib/python3.10/dist-packages/keras/src/losses.py\", line 270, in call\n\n  File \"/usr/local/lib/python3.10/dist-packages/keras/src/losses.py\", line 2454, in sparse_categorical_crossentropy\n\n  File \"/usr/local/lib/python3.10/dist-packages/keras/src/backend.py\", line 5775, in sparse_categorical_crossentropy\n\nReceived a label value of 1380 which is outside the valid range of [0, 1147).  Label values: 176 1061 1022 514 14 588 78 598 1076 522 208 231 815 840 882 361 641 364 361 602 361 1219 812 1380 990 842 1363 598 1005 703 273 73 572 885 361 387 151 74 281 11 385 545 47 713 310 1202 106 1258 60 703 499 737 364 585 593 141 246 935 930 1222 43 61 151 109\n\t [[{{node sparse_categorical_crossentropy/SparseSoftmaxCrossEntropyWithLogits/SparseSoftmaxCrossEntropyWithLogits}}]] [Op:__inference_train_function_4543]"
          ]
        }
      ],
      "source": [
        "import tensorflow as tf\n",
        "from tensorflow.keras.models import Sequential\n",
        "from tensorflow.keras.layers import Dense, Embedding, GlobalAveragePooling1D, Dropout\n",
        "from sklearn.model_selection import train_test_split\n",
        "from sklearn.preprocessing import LabelEncoder\n",
        "from tensorflow.keras.preprocessing.text import Tokenizer\n",
        "from tensorflow.keras.preprocessing.sequence import pad_sequences\n",
        "import pandas as pd\n",
        "import numpy as np\n",
        "import re\n",
        "\n",
        "# 데이터 불러오기\n",
        "df = pd.read_csv('/content/drugLibTrain_raw_new.tsv', sep=\"\\t\", encoding='latin1')\n",
        "\n",
        "# 필요한 열 선택 및 결측치 제거\n",
        "df = df[['urlDrugName', 'benefitsReview', 'sideEffectsReview', 'commentsReview', 'condition']]\n",
        "df = df.dropna()\n",
        "\n",
        "# 모든 리뷰 합치기\n",
        "df['all_reviews'] = df['benefitsReview'] + ' ' + df['sideEffectsReview'] + ' ' + df['commentsReview']\n",
        "\n",
        "# 텍스트 전처리\n",
        "df['all_reviews'] = df['all_reviews'].apply(lambda x: re.sub(r'[^a-zA-Z\\s]', '', x))\n",
        "df['all_reviews'] = df['all_reviews'].str.lower()\n",
        "df['condition'] = df['condition'].str.lower()\n",
        "\n",
        "# 토큰화 및 불용어 제거\n",
        "tokenizer = Tokenizer()\n",
        "tokenizer.fit_on_texts(df['all_reviews'])\n",
        "review_sequences = tokenizer.texts_to_sequences(df['all_reviews'])\n",
        "max_length = max([len(seq) for seq in review_sequences])\n",
        "df_review_padded = pad_sequences(review_sequences, maxlen=max_length, padding='post')\n",
        "df['all_reviews'] = list(df_review_padded)\n",
        "\n",
        "# 데이터 분할\n",
        "X = df[['all_reviews']]\n",
        "y = df[['condition']]\n",
        "label_encoder = LabelEncoder()\n",
        "y_encoded = label_encoder.fit_transform(y)\n",
        "X_train, X_test, y_train, y_test = train_test_split(X, y_encoded, test_size=0.2, random_state=42)\n",
        "\n",
        "# NumPy 배열을 텐서로 변환\n",
        "X_train = np.array(X_train['all_reviews'].tolist())\n",
        "X_test = np.array(X_test['all_reviews'].tolist())\n",
        "# 모델 생성\n",
        "model = Sequential()\n",
        "embedding_dim = 100\n",
        "vocab_size = len(tokenizer.word_index) + 1\n",
        "model.add(Embedding(input_dim=vocab_size, output_dim=embedding_dim))\n",
        "model.add(GlobalAveragePooling1D())\n",
        "model.add(Dense(128, activation='relu'))\n",
        "model.add(Dropout(0.5))\n",
        "# 출력 레이어의 노드 수를 클래스의 수로 변경\n",
        "num_classes = len(np.unique(y_train))\n",
        "model.add(Dense(num_classes, activation='softmax'))\n",
        "model.compile(optimizer='adam', loss='sparse_categorical_crossentropy', metrics=['accuracy'])\n",
        "\n",
        "# 모델 훈련\n",
        "model.fit(X_train, y_train, epochs=10, batch_size=64, validation_split=0.2)\n"
      ]
    },
    {
      "cell_type": "code",
      "source": [],
      "metadata": {
        "id": "O9SP1a7HgVDE"
      },
      "execution_count": null,
      "outputs": []
    }
  ]
}